<?xml version="1.0"?>
<sdf version="1.9">
  <model name="qcar_simple">
    <pose>0 0 0.15 0 0 0</pose>

    <link name="base_link">
      <inertial>
        <mass>5.0</mass>
        <inertia><ixx>0.1</ixx><iyy>0.1</iyy><izz>0.1</izz></inertia>
      </inertial>
      <collision name="base_collision">
        <geometry><box><size>0.55 0.35 0.18</size></box></geometry>
      </collision>
      <visual name="base_visual">
        <geometry><box><size>0.55 0.35 0.18</size></box></geometry>
        <material><ambient>0.1 0.6 0.1 1</ambient><diffuse>0.1 0.6 0.1 1</diffuse></material>
      </visual>
    </link>

    <link name="left_wheel">
      <pose>0 0.22 0.0 1.5708 0 0</pose>
      <collision name="collision"><geometry><cylinder><radius>0.07</radius><length>0.04</length></cylinder></geometry></collision>
      <visual name="visual"><geometry><cylinder><radius>0.07</radius><length>0.04</length></cylinder></geometry></visual>
    </link>

    <link name="right_wheel">
      <pose>0 -0.22 0.0 1.5708 0 0</pose>
      <collision name="collision"><geometry><cylinder><radius>0.07</radius><length>0.04</length></cylinder></geometry></collision>
      <visual name="visual"><geometry><cylinder><radius>0.07</radius><length>0.04</length></cylinder></geometry></visual>
    </link>

    <joint name="left_wheel_joint" type="revolute">
      <parent>base_link</parent><child>left_wheel</child>
      <axis><xyz>0 0 1</xyz></axis>
    </joint>

    <joint name="right_wheel_joint" type="revolute">
      <parent>base_link</parent><child>right_wheel</child>
      <axis><xyz>0 0 1</xyz></axis>
    </joint>

    <link name="lidar_link">
      <pose>0.15 0 0.18 0 0 0</pose>
      <sensor name="gpu_lidar" type="gpu_lidar">
        <topic>/scan</topic>
        <update_rate>10</update_rate>
        <ray>
          <scan>
            <horizontal>
              <samples>720</samples>
              <resolution>1</resolution>
              <min_angle>-3.14159</min_angle>
              <max_angle>3.14159</max_angle>
            </horizontal>
          </scan>
          <range>
            <min>0.08</min>
            <max>12.0</max>
            <resolution>0.01</resolution>
          </range>
        </ray>
        <always_on>true</always_on>
        <visualize>true</visualize>
      </sensor>
    </link>

    <joint name="lidar_joint" type="fixed">
      <parent>base_link</parent><child>lidar_link</child>
    </joint>

    <plugin filename="gz-sim-diff-drive-system" name="gz::sim::systems::DiffDrive">
      <left_joint>left_wheel_joint</left_joint>
      <right_joint>right_wheel_joint</right_joint>
      <wheel_separation>0.44</wheel_separation>
      <wheel_radius>0.07</wheel_radius>
      <topic>/cmd_vel</topic>
      <odom_topic>/odom</odom_topic>
      <tf_topic>/tf</tf_topic>
      <frame_id>odom</frame_id>
      <child_frame_id>base_link</child_frame_id>
      <odom_publish_frequency>30</odom_publish_frequency>
    </plugin>

  </model>
</sdf>
