<?xml version="1.0"?>
<sdf version="1.9">
  <model name="qcar_planb">
    <pose>0 0 0.12 0 0 0</pose>

    <link name="base_link">
      <inertial>
        <mass>5.0</mass>
        <inertia><ixx>0.18</ixx><iyy>0.22</iyy><izz>0.28</izz></inertia>
      </inertial>
      <collision name="body_collision">
        <geometry><box><size>0.58 0.36 0.16</size></box></geometry>
      </collision>
      <visual name="lower_chassis">
        <pose>0 0 0.02 0 0 0</pose>
        <geometry><box><size>0.62 0.38 0.10</size></box></geometry>
        <material><ambient>0.02 0.08 0.18 1</ambient><diffuse>0.02 0.08 0.18 1</diffuse></material>
      </visual>
      <visual name="top_cover">
        <pose>-0.03 0 0.105 0 0 0</pose>
        <geometry><box><size>0.46 0.30 0.08</size></box></geometry>
        <material><ambient>0.0 0.45 0.95 1</ambient><diffuse>0.0 0.45 0.95 1</diffuse></material>
      </visual>
      <visual name="front_marker">
        <pose>0.31 0 0.08 0 0 0</pose>
        <geometry><box><size>0.02 0.26 0.04</size></box></geometry>
        <material><ambient>1 1 1 1</ambient><diffuse>1 1 1 1</diffuse></material>
      </visual>
    </link>

    <link name="front_left_wheel">
      <pose>0.20 0.23 0.0 1.5708 0 0</pose>
      <collision name="collision"><geometry><cylinder><radius>0.065</radius><length>0.04</length></cylinder></geometry></collision>
      <visual name="visual"><geometry><cylinder><radius>0.065</radius><length>0.04</length></cylinder></geometry><material><ambient>0.02 0.02 0.02 1</ambient><diffuse>0.02 0.02 0.02 1</diffuse></material></visual>
    </link>
    <link name="rear_left_wheel">
      <pose>-0.20 0.23 0.0 1.5708 0 0</pose>
      <collision name="collision"><geometry><cylinder><radius>0.065</radius><length>0.04</length></cylinder></geometry></collision>
      <visual name="visual"><geometry><cylinder><radius>0.065</radius><length>0.04</length></cylinder></geometry><material><ambient>0.02 0.02 0.02 1</ambient><diffuse>0.02 0.02 0.02 1</diffuse></material></visual>
    </link>
    <link name="front_right_wheel">
      <pose>0.20 -0.23 0.0 1.5708 0 0</pose>
      <collision name="collision"><geometry><cylinder><radius>0.065</radius><length>0.04</length></cylinder></geometry></collision>
      <visual name="visual"><geometry><cylinder><radius>0.065</radius><length>0.04</length></cylinder></geometry><material><ambient>0.02 0.02 0.02 1</ambient><diffuse>0.02 0.02 0.02 1</diffuse></material></visual>
    </link>
    <link name="rear_right_wheel">
      <pose>-0.20 -0.23 0.0 1.5708 0 0</pose>
      <collision name="collision"><geometry><cylinder><radius>0.065</radius><length>0.04</length></cylinder></geometry></collision>
      <visual name="visual"><geometry><cylinder><radius>0.065</radius><length>0.04</length></cylinder></geometry><material><ambient>0.02 0.02 0.02 1</ambient><diffuse>0.02 0.02 0.02 1</diffuse></material></visual>
    </link>

    <joint name="front_left_wheel_joint" type="revolute"><parent>base_link</parent><child>front_left_wheel</child><axis><xyz>0 0 1</xyz></axis></joint>
    <joint name="rear_left_wheel_joint" type="revolute"><parent>base_link</parent><child>rear_left_wheel</child><axis><xyz>0 0 1</xyz></axis></joint>
    <joint name="front_right_wheel_joint" type="revolute"><parent>base_link</parent><child>front_right_wheel</child><axis><xyz>0 0 1</xyz></axis></joint>
    <joint name="rear_right_wheel_joint" type="revolute"><parent>base_link</parent><child>rear_right_wheel</child><axis><xyz>0 0 1</xyz></axis></joint>

    <link name="lidar_link">
      <pose>0.12 0 0.23 0 0 0</pose>
      <sensor name="lidar" type="gpu_lidar">
        <topic>/qcar/scan</topic>
        <update_rate>10</update_rate>
        <ray>
          <scan><horizontal><samples>720</samples><resolution>1</resolution><min_angle>-3.14159</min_angle><max_angle>3.14159</max_angle></horizontal></scan>
          <range><min>0.08</min><max>12.0</max><resolution>0.01</resolution></range>
        </ray>
        <always_on>true</always_on>
        <visualize>true</visualize>
      </sensor>
    </link>
    <joint name="lidar_joint" type="fixed"><parent>base_link</parent><child>lidar_link</child></joint>

    <link name="camera_link">
      <pose>0.31 0 0.20 0 0 0</pose>
      <sensor name="front_camera" type="camera">
        <topic>/qcar/camera/image_raw</topic>
        <update_rate>15</update_rate>
        <camera>
          <horizontal_fov>1.047</horizontal_fov>
          <image><width>640</width><height>480</height><format>R8G8B8</format></image>
          <clip><near>0.05</near><far>50</far></clip>
        </camera>
        <always_on>true</always_on>
        <visualize>true</visualize>
      </sensor>
    </link>
    <joint name="camera_joint" type="fixed"><parent>base_link</parent><child>camera_link</child></joint>

    <plugin filename="gz-sim-diff-drive-system" name="gz::sim::systems::DiffDrive">
      <left_joint>front_left_wheel_joint</left_joint>
      <left_joint>rear_left_wheel_joint</left_joint>
      <right_joint>front_right_wheel_joint</right_joint>
      <right_joint>rear_right_wheel_joint</right_joint>
      <wheel_separation>0.46</wheel_separation>
      <wheel_radius>0.065</wheel_radius>
      <topic>/qcar/cmd_vel</topic>
      <odom_topic>/qcar/odom</odom_topic>
      <tf_topic>/tf</tf_topic>
      <frame_id>odom</frame_id>
      <child_frame_id>base_link</child_frame_id>
      <odom_publish_frequency>30</odom_publish_frequency>
    </plugin>
  </model>
</sdf>
